ERROR:2018-12-15 11:34:23,368:Asyncioimsender.py:283:socket creation Failure:[Errno 111] Connection refused
